Workbook

Sheet 公司查詢
A1: 外電綜合報導查詢系統
A3: 查詢條件 請輸入股號或公司名稱（例如：3017 或 奇鋐）
A6: =IF(A4="","請在上方輸入查詢條件","查詢結果：" & A4 & " 共找到 " & MAX(查詢輔助!C:C) & " 筆報導")
A8: 查詢結果
A10: =IF(A4="","",IF(MAX(查詢輔助!C:C)<1,"",INDEX(完整內容收錄!B:B,MATCH(1,查詢輔助!C:C,0))&" │ 券商："&INDEX(完整內容收錄!E:E,MATCH(1,查詢輔助!C:C,0))&" │ "&INDEX(報導總表!F:F,MATCH(1,查詢輔助!C:C,0))&" │ "&INDEX(報導總表!G:G,MATCH(1,查詢輔助!C:C,0))))
A11: =IF(A4="","",IF(MAX(查詢輔助!C:C)<1,"",INDEX(完整內容收錄!F:F,MATCH(1,查詢輔助!C:C,0))))
A12: =IF(A4="","",IF(MAX(查詢輔助!C:C)<1,"","標籤："&INDEX(完整內容收錄!G:G,MATCH(1,查詢輔助!C:C,0))))
A14: =IF(A4="","",IF(MAX(查詢輔助!C:C)<2,"",INDEX(完整內容收錄!B:B,MATCH(2,查詢輔助!C:C,0))&" │ 券商："&INDEX(完整內容收錄!E:E,MATCH(2,查詢輔助!C:C,0))&" │ "&INDEX(報導總表!F:F,MATCH(2,查詢輔助!C:C,0))&" │ "&INDEX(報導總表!G:G,MATCH(2,查詢輔助!C:C,0))))
A15: =IF(A4="","",IF(MAX(查詢輔助!C:C)<2,"",INDEX(完整內容收錄!F:F,MATCH(2,查詢輔助!C:C,0))))
A16: =IF(A4="","",IF(MAX(查詢輔助!C:C)<2,"","標籤："&INDEX(完整內容收錄!G:G,MATCH(2,查詢輔助!C:C,0))))
A18: =IF(A4="","",IF(MAX(查詢輔助!C:C)<3,"",INDEX(完整內容收錄!B:B,MATCH(3,查詢輔助!C:C,0))&" │ 券商："&INDEX(完整內容收錄!E:E,MATCH(3,查詢輔助!C:C,0))&" │ "&INDEX(報導總表!F:F,MATCH(3,查詢輔助!C:C,0))&" │ "&INDEX(報導總表!G:G,MATCH(3,查詢輔助!C:C,0))))
A19: =IF(A4="","",IF(MAX(查詢輔助!C:C)<3,"",INDEX(完整內容收錄!F:F,MATCH(3,查詢輔助!C:C,0))))
A20: =IF(A4="","",IF(MAX(查詢輔助!C:C)<3,"","標籤："&INDEX(完整內容收錄!G:G,MATCH(3,查詢輔助!C:C,0))))
A22: =IF(A4="","",IF(MAX(查詢輔助!C:C)<4,"",INDEX(完整內容收錄!B:B,MATCH(4,查詢輔助!C:C,0))&" │ 券商："&INDEX(完整內容收錄!E:E,MATCH(4,查詢輔助!C:C,0))&" │ "&INDEX(報導總表!F:F,MATCH(4,查詢輔助!C:C,0))&" │ "&INDEX(報導總表!G:G,MATCH(4,查詢輔助!C:C,0))))
A23: =IF(A4="","",IF(MAX(查詢輔助!C:C)<4,"",INDEX(完整內容收錄!F:F,MATCH(4,查詢輔助!C:C,0))))
A24: =IF(A4="","",IF(MAX(查詢輔助!C:C)<4,"","標籤："&INDEX(完整內容收錄!G:G,MATCH(4,查詢輔助!C:C,0))))
A26: =IF(A4="","",IF(MAX(查詢輔助!C:C)<5,"",INDEX(完整內容收錄!B:B,MATCH(5,查詢輔助!C:C,0))&" │ 券商："&INDEX(完整內容收錄!E:E,MATCH(5,查詢輔助!C:C,0))&" │ "&INDEX(報導總表!F:F,MATCH(5,查詢輔助!C:C,0))&" │ "&INDEX(報導總表!G:G,MATCH(5,查詢輔助!C:C,0))))
A27: =IF(A4="","",IF(MAX(查詢輔助!C:C)<5,"",INDEX(完整內容收錄!F:F,MATCH(5,查詢輔助!C:C,0))))
A28: =IF(A4="","",IF(MAX(查詢輔助!C:C)<5,"","標籤："&INDEX(完整內容收錄!G:G,MATCH(5,查詢輔助!C:C,0))))
A30: =IF(A4="","",IF(MAX(查詢輔助!C:C)<6,"",INDEX(完整內容收錄!B:B,MATCH(6,查詢輔助!C:C,0))&" │ 券商："&INDEX(完整內容收錄!E:E,MATCH(6,查詢輔助!C:C,0))&" │ "&INDEX(報導總表!F:F,MATCH(6,查詢輔助!C:C,0))&" │ "&INDEX(報導總表!G:G,MATCH(6,查詢輔助!C:C,0))))
A31: =IF(A4="","",IF(MAX(查詢輔助!C:C)<6,"",INDEX(完整內容收錄!F:F,MATCH(6,查詢輔助!C:C,0))))
A32: =IF(A4="","",IF(MAX(查詢輔助!C:C)<6,"","標籤："&INDEX(完整內容收錄!G:G,MATCH(6,查詢輔助!C:C,0))))
A34: =IF(A4="","",IF(MAX(查詢輔助!C:C)<7,"",INDEX(完整內容收錄!B:B,MATCH(7,查詢輔助!C:C,0))&" │ 券商："&INDEX(完整內容收錄!E:E,MATCH(7,查詢輔助!C:C,0))&" │ "&INDEX(報導總表!F:F,MATCH(7,查詢輔助!C:C,0))&" │ "&INDEX(報導總表!G:G,MATCH(7,查詢輔助!C:C,0))))
A35: =IF(A4="","",IF(MAX(查詢輔助!C:C)<7,"",INDEX(完整內容收錄!F:F,MATCH(7,查詢輔助!C:C,0))))
A36: =IF(A4="","",IF(MAX(查詢輔助!C:C)<7,"","標籤："&INDEX(完整內容收錄!G:G,MATCH(7,查詢輔助!C:C,0))))
A38: =IF(A4="","",IF(MAX(查詢輔助!C:C)<8,"",INDEX(完整內容收錄!B:B,MATCH(8,查詢輔助!C:C,0))&" │ 券商："&INDEX(完整內容收錄!E:E,MATCH(8,查詢輔助!C:C,0))&" │ "&INDEX(報導總表!F:F,MATCH(8,查詢輔助!C:C,0))&" │ "&INDEX(報導總表!G:G,MATCH(8,查詢輔助!C:C,0))))
A39: =IF(A4="","",IF(MAX(查詢輔助!C:C)<8,"",INDEX(完整內容收錄!F:F,MATCH(8,查詢輔助!C:C,0))))
A40: =IF(A4="","",IF(MAX(查詢輔助!C:C)<8,"","標籤："&INDEX(完整內容收錄!G:G,MATCH(8,查詢輔助!C:C,0))))
A42: =IF(A4="","",IF(MAX(查詢輔助!C:C)<9,"",INDEX(完整內容收錄!B:B,MATCH(9,查詢輔助!C:C,0))&" │ 券商："&INDEX(完整內容收錄!E:E,MATCH(9,查詢輔助!C:C,0))&" │ "&INDEX(報導總表!F:F,MATCH(9,查詢輔助!C:C,0))&" │ "&INDEX(報導總表!G:G,MATCH(9,查詢輔助!C:C,0))))
A43: =IF(A4="","",IF(MAX(查詢輔助!C:C)<9,"",INDEX(完整內容收錄!F:F,MATCH(9,查詢輔助!C:C,0))))
A44: =IF(A4="","",IF(MAX(查詢輔助!C:C)<9,"","標籤："&INDEX(完整內容收錄!G:G,MATCH(9,查詢輔助!C:C,0))))
A46: =IF(A4="","",IF(MAX(查詢輔助!C:C)<10,"",INDEX(完整內容收錄!B:B,MATCH(10,查詢輔助!C:C,0))&" │ 券商："&INDEX(完整內容收錄!E:E,MATCH(10,查詢輔助!C:C,0))&" │ "&INDEX(報導總表!F:F,MATCH(10,查詢輔助!C:C,0))&" │ "&INDEX(報導總表!G:G,MATCH(10,查詢輔助!C:C,0))))
A47: =IF(A4="","",IF(MAX(查詢輔助!C:C)<10,"",INDEX(完整內容收錄!F:F,MATCH(10,查詢輔助!C:C,0))))
A48: =IF(A4="","",IF(MAX(查詢輔助!C:C)<10,"","標籤："&INDEX(完整內容收錄!G:G,MATCH(10,查詢輔助!C:C,0))))
A50: ※ 本系統使用傳統Excel公式，相容所有Excel版本（最多顯示10筆報導）

Sheet 報導總表
A1: 編號 | B1: 日期 | C1: 公司 | D1: 股號 | E1: 券商來源 | F1: 報導重點分類 | G1: 重要性 | H1: 標籤
A2: 001 | B2: 2025/11/10 | C2: 群聯 | D2: 8299 | E2: 美系大行 | F2: 營運展望 | G2: ⭐⭐⭐⭐ | H2: #NAND #SSD #企業級
A3: 002 | B3: 2025/11/10 | C3: GB200趨勢 | D3: - | E3: 美系大行 | F3: 產業趨勢 | G3: ⭐⭐⭐⭐⭐ | H3: #GB200 #NVL72 #GB300
A4: 003 | B4: 2025/11/10 | C4: 緯穎 | D4: 6669 | E4: 澳系券商 | F4: EPS上修 | G4: ⭐⭐⭐⭐⭐ | H4: #AI伺服器 #ECB #AWS
A5: 004 | B5: 2025/11/10 | C5: 緯穎 | D5: 6669 | E5: 亞系 | F5: 市佔觀察 | G5: ⭐⭐⭐⭐ | H5: #ASIC #L10 #L11
A6: 005 | B6: 2025/11/10 | C6: 京元電 | D6: 2449 | E6: 美系券商 | F6: EPS上修 | G6: ⭐⭐⭐⭐⭐ | H6: #GPU #ASIC #測試
A7: 006 | B7: 2025/11/10 | C7: 勤誠 | D7: 8210 | E7: 美系券商 | F7: EPS上修 | G7: ⭐⭐⭐⭐ | H7: #機殼機櫃 #AI伺服器
A8: 007 | B8: 2025/11/10 | C8: 貿聯 | D8: 3665 | E8: 美系券商 | F8: EPS上修 | G8: ⭐⭐⭐⭐ | H8: #AEC #機櫃連接
A9: 008 | B9: 2025/11/10 | C9: 奇鋐 | D9: 3017 | E9: 美系大行 | F9: 營運展望 | G9: ⭐⭐⭐ | H9: #散熱 #法說會1112
A10: 009 | B10: 2025/11/07 | C10: 創意 | D10: 3443 | E10: 美系大行 | F10: EPS上修 | G10: ⭐⭐⭐⭐⭐ | H10: #CoWoS #Google #TPU
A11: 010 | B11: 2025/11/07 | C11: 建準 | D11: 2421 | E11: 美系大行 | F11: 營運展望 | G11: ⭐⭐⭐⭐ | H11: #散熱 #風扇 #CDU
A12: 011 | B12: 2025/11/07 | C12: 南電 | D12: 8046 | E12: 美系券商 | F12: 營運展望 | G12: ⭐⭐⭐⭐⭐ | H12: #ABF #BT #ASIC
A13: 012 | B13: 2025/11/07 | C13: 致茂 | D13: 2360 | E13: 美系大行 | F13: 營運展望 | G13: ⭐⭐⭐ | H13: #測試設備
A14: 013 | B14: 2025/11/05 | C14: 奇鋐 | D14: 3017 | E14: 澳系券商 | F14: EPS上修 | G14: ⭐⭐⭐⭐⭐ | H14: #水冷 #機殼 #VC
A15: 014 | B15: 2025/11/05 | C15: 富世達 | D15: 6805 | E15: 美系券商、亞系券商 | F15: EPS上修 | G15: ⭐⭐⭐⭐ | H15: #QD #水冷 #GB300
... A20: 019 | B20: 2025/11/05 | C20: 聯詠 | D20: 3034 | E20: 亞系券商 | F20: 降評 | G20: ⭐⭐ | H20: #IC設計 #電視
A21: 020 | C21: SK海力士 三星電子 | E21: 瑞銀 | F21: 目標價上調 | G21: ⭐⭐⭐⭐⭐ | H21: #DRAM #DDR #HBM #記憶體
A22: 021 | B22: 2025/10/28 | C22: 貿聯 | D22: 3665 | E22: 美系大行 | F22: EPS上修 | G22: ⭐⭐⭐⭐⭐ | H22: #AEC #電源互連 #GPU
A23: 022 | B23: 2025/10/28 | C23: 奇鋐 | D23: 3017 | E23: 亞系券商 | F23: EPS上修 | G23: ⭐⭐⭐⭐⭐ | H23: #水冷 #ASIC #GPU
A24: 023 | B24: 2025/10/28 | C24: 景碩 | D24: 3189 | E24: 美系券商 | F24: 營運展望 | G24: ⭐⭐⭐⭐ | H24: #BT #ABF #現增
A25: 024 | B25: 2025/10/29 | C25: 國巨 | D25: 2327 | E25: 美系大行 | F25: 升評升目標 | G25: ⭐⭐⭐⭐⭐ | H25: #被動元件 #鉭電容
A26: 025 | B26: 2025/10/29 | C26: 京元電 日月光 | D26: 2449 3711 | E26: 美系大行 | F26: EPS上修 | G26: ⭐⭐⭐⭐⭐ | H26: #封測 #漲價 #AI
A27: 026 | B27: 2025/10/29 | C27: 聯發科 | D27: 2454 | E27: 美系大行 | F27: 降目標 | G27: ⭐⭐⭐ | H27: #天璣 #成本上升
A28: 027 | B28: 2025/10/29 | C28: 致茂 | D28: 2360 | E28: 美系大行 | F28: EPS上修 | G28: ⭐⭐⭐⭐ | H28: #測試設備 #PSU #BBU
A29: 028 | B29: 2025/10/29 | C29: 欣興 | D29: 3037 | E29: 美系券商 | F29: 營運展望 | G29: ⭐⭐⭐⭐ | H29: #ABF #BT #CPO
A30: 029 | B30: 2025/11/06 | C30: 華邦電 | D30: 2344 | E30: 美系大行 | F30: EPS上修 | G30: ⭐⭐⭐⭐⭐ | H30: #DDR #NOR #CUBE
A31: 030 | B31: 2025/11/06 | C31: 金像電 | D31: 2368 | E31: 亞系券商 | F31: EPS上修 | G31: ⭐⭐⭐⭐ | H31: #AI PCB #800G #MSCI
A32: 031 | B32: 2025/11/06 | C32: 東元 | D32: 1504 | E32: 美系券商 | F32: EPS上修 | G32: ⭐⭐⭐⭐ | H32: #馬達 #資料中心 #MSCI
A33: 032 | B33: 2025/11/06 | C33: 貿聯 | D33: 3665 | E33: 美系大行 | F33: 營運展望 | G33: ⭐⭐⭐⭐ | H33: #AEC #HPC #MSCI
A34: 033 | B34: 2025/11/06 | C34: 鴻海 | D34: 2317 | E34: 美系大行 | F34: 營運展望 | G34: ⭐⭐⭐⭐ | H34: #10月營收新高 #伺服器
A35: 034 | B35: 2025/11/06 | C35: 南電 | D35: 8046 | E35: 美系券商 | F35: 營運展望 | G35: ⭐⭐⭐⭐⭐ | H35: #ABF #BT #漲價
A36: 035 | B36: 2025/11/03 | C36: 聯發科 | D36: 2454 | E36: 美系券商 | F36: 降評 | G36: ⭐⭐⭐ | H36: #毛利率下降 #ASIC
A37: 036 | B37: 2025/11/03 | C37: 散熱產業 | D37: 3017 6805 3324 2421 | E37: 美系大行 | F37: EPS上修 | G37: ⭐⭐⭐⭐⭐ | H37: #GB300 #水冷 #散熱
A38: 037 | B38: 2025/11/03 | C38: 國巨 | D38: 2327 | E38: 美系券商 | F38: EPS上修 | G38: ⭐⭐⭐⭐ | H38: #被動元件 #鉭電容
A39: 038 | B39: 2025/11/03 | C39: 嘉澤 | D39: 3533 | E39: 美系大行 | F39: 降目標 | G39: ⭐⭐⭐ | H39: #QD #VR200
A40: 039 | B40: 2025/10/31 | C40: AI供應鏈 | D40: - | E40: 美系大行 | F40: 產業趨勢 | G40: ⭐⭐⭐⭐⭐ | H40: #CoWoS #AMD #Broadcom
A41: 040 | B41: 2025/10/31 | C41: 京元電 | D41: 2449 | E41: 亞系券商 | F41: EPS上修 | G41: ⭐⭐⭐⭐ | H41: #ASIC #TPU
A42: 041 | B42: 2025/10/31 | C42: 日月光 | D42: 3711 | E42: 美系大行 | F42: 營運展望 | G42: ⭐⭐⭐⭐ | H42: #封裝 #LEAP
A43: 042 | B43: 2025/10/31 | C43: 川湖 | D43: 2059 | E43: 美系大行 | F43: EPS上修 | G43: ⭐⭐⭐⭐⭐ | H43: #機櫃 #AMD Helios
A44: 043 | B44: 2025/10/31 | C44: 台達電 | D44: 2308 | E44: 美系大行 | F44: EPS上修 | G44: ⭐⭐⭐⭐⭐ | H44: #Infra #OPM #首選
...

Sheet 完整內容收錄
A1: 編號 | B1: 日期 | C1: 公司 | D1: 股號 | E1: 券商來源 | F1: 完整報導內容 | G1: 標籤
A2: 001 | B2: 2025/11/10 | C2: 群聯 | D2: 8299 | E2: 美系大行 | F2: • 美系大行指出明年NAND已全數售罄，各應用市場客戶都在向群聯尋求供貨保障，由於群聯有穩定供應紀錄，券商對未來幾季的庫存水準充滿信心。 • 企業級SSD業務明年預估占營收比重達20%，高於3Q25的8%。 • 券商重申正向評等不變。 | G2: #NAND #SSD #企業級
A3: 002 | B3: 2025/11/10 | C3: GB200趨勢 | D3: - | E3: 美系大行 | F3: • 美系大行預估4Q總機櫃出貨量可望顯著成長至14,000–15,000台，高於第3季的8,000–8,500台。 • GB300生產已啟動，將順利放量，未聞任何良率問題。 | G3: #GB200 #NVL72 #GB300
A4: 003 | B4: 2025/11/10 | C4: 緯穎 | D4: 6669 | E4: 澳系券商 | F4: • 澳系券商上修25-27年EPS至$274/$346/$441，以後年18xPE評價，同步升目標，也是目前市場最高。 • 券商表示發行 20 億美元可轉換債（約稀釋 6%），可能意味 2026 年需求展望強勁，與 2024 年下半年發行 ECB/GDR 類似，隨後於今年營收強勁成長。 • 大方向上AWS ASIC 與 Nvidia/AMD 新客戶將持續推動明年強勁成長，細節上若水冷伺服器比例上升，ASP也會有上行空間。 | G4: #AI伺服器 #ECB #AWS
A5: 004 | B5: 2025/11/10 | C5: 緯穎 | D5: 6669 | E5: 亞系 | F5: 另家亞系觀察AWS ASIC（UBB 層級）市佔上升，新增於現有的 L10（trays）與 L11（機櫃）業務之上。 | G5: #ASIC #L10 #L11
A6: 005 | B6: 2025/11/10 | C6: 京元電 | D6: 2449 | E6: 美系券商 | F6: • 3Q 第三季財報亮眼，毛利率達 36%, 淨利季增6%等優於美系券商預期。 • 券商預估4Q營收季增約 6–8%，且毛利率可望再進一步提升。 • 受惠於 AI 需求強勁與測試時數延長，京元電預期整體 GPU 營收明年將年增超過 60%。 • 除了GPU, 將受惠於強勁的 AI ASIC 市場，特別是 Google 的 TPU 與基於 ARM 架構的 CPU。 • 計畫到 2027 年將 AI ASIC 測試機台增加至 350 台，遠高於目前 AI GPU 測試機台約 90 台。 • 美系券商上修25-27年EPS至$9/$10/$14，並給予市場最高的目標。 | G6: #GPU #ASIC #測試
A7: 006 | B7: 2025/11/10 | C7: 勤誠 | D7: 8210 | E7: 美系券商 | F7: • 3Q毛利優於預期；機殼與機櫃市佔提升推動成長，展望4Q，預期GPU與ASIC伺服器的需求依然穩健（～3Q的AI相關業務占營收比重超過50%）。 • 客製化的部位明年有望站上雙位數。 • 美國新產線將年底開始小量出貨；馬來西亞新廠進度正常，預計明年中量產。 • 另一座位於德州的大型產能計畫將於年底定案，預計2027年開始放量。 • 券商上修今明年至$27.9/$39.7，以明年30xPE評價，同步升目標。 | G7: #機殼機櫃 #AI伺服器
A8: 007 | B8: 2025/11/10 | C8: 貿聯 | D8: 3665 | E8: 美系券商 | F8: • 從機櫃內連接擴展至機櫃間連接（rack-to-rack），AEC 需求強勁。 • 即使 CPO 逐步量產，AEC 需求仍將保持強勁。 • 由於電力產品毛利率高於數據產品，該類業務比重上升將持續推升整體毛利率。 • 美系券商上修25-26年EPS至$46.9/$62，同步升標。 | G8: #AEC #機櫃連接
A9: 008 | B9: 2025/11/10 | C9: 奇鋐 | D9: 3017 | E9: 美系大行 | F9: • 美系大行表示10 月營收創歷史新高，超預期 8%；第四季可能上修。 • 待11/12 法說會說明，重申正向評等不變。 | G9: #散熱 #法說會1112
A10: 009 | B10: 2025/11/07 | C10: 創意 | D10: 3443 | E10: 美系大行 | F10: • 美系大行調升26-27年EPS至$40.7/$56.3，以明年44xPE評價，同步升目標。 • 券商預期明年至少有30%的營收貢獻來自Google,，根據Google TPU v6 的伺服器配置，推算 CoWoS 模組的 3 奈米 TPU 將對應約 75 萬顆 CPU 的需求，單價約 800 美元，因此上修 Google CPU 專案的貢獻。 • 其他如：加密貨幣動能至少延續至1H26；正與 Rivos 合作一項 3 奈米專案，並將採用 CoWoS 封裝、xAI 專案Turnkey 2（TK2），2H26貢獻營收；FuriosaAI 5 奈米 AI 加速器已完成流片；Meta集中於 NRE收入等。 | G10: #CoWoS #Google #TPU
A11: 010 | B11: 2025/11/07 | C11: 建準 | D11: 2421 | E11: 美系大行 | F11: 3Q毛利率創下歷史新高，美系大行對明年毛利率持續走高觀察正向，12月底前完成cold plate 風扇的客戶測試，並於2026年第一季開始量產，另外明年也會展開CDU量產。 | G11: #散熱 #風扇 #CDU
A12: 011 | B12: 2025/11/07 | C12: 南電 | D12: 8046 | E12: 美系券商 | F12: • 美系券商預期4Q ABF漲幅季增低至中個位數百分比（相較第三季為低個位數百分比），且於2026年第一季將加速上升。 • 明年有新供應商加入T-glass，但仍追不上需求。 • 此外，目前已有一個ASIC案，明年會再新增一個，另還有一個CSP CPU專案在明下半年量產。 • 最後觀察到E-glass交期正在拉長，顯示不僅高階ABF載板，連中低階產品線的價格環境也可能轉趨有利。 • 綜上，重申正向評等不變。 | G12: #ABF #BT #ASIC
A13: 012 | B13: 2025/11/07 | C13: 致茂 | D13: 2360 | E13: 美系大行 | F13: • 本季QTD營收達成美系大行預估數36%，優於預期。 • 券商持續正向看待致茂在電源與半導體測試領域的領先地位。 | G13: #測試設備
A14: 013 | B14: 2025/11/05 | C14: 奇鋐 | D14: 3017 | E14: 澳系券商 | F14: • 澳系券商觀察三大成長引擎：1）明年GPU+ASIC 明年貢獻水冷營收翻倍 2）機殼明年產能增4成，rack產能年增6倍 3）iPhone 今年開始導入VC, 明年新增iPad。 • 券商上調25-27年EPS至$48/$72.5/$90，給予27年的20xPE評價，同步升目標。 | G14: #水冷 #機殼 #VC
A15: 014 | B15: 2025/11/05 | C15: 富世達 | D15: 6805 | E15: 美系券商、亞系券商 | F15: • 美系券商認為3Q毛利率27.7%優於預期，QD伴隨水冷滲透率提升而加速成長，Nvidia VR 運算托盤採用 CPX 規格也會帶來新增 QD 需求。 • 美系預期4Q營收季增15%、年增48%（～手機軸承+GB300貢獻）。 • 預估今明年EPS$31.4/$57.5,給予後年22xPE評價，同步升目標。 | G15: #QD #水冷 #GB300
... A20: 019 | B20: 2025/11/05 | C20: 聯詠 | D20: 3034 | E20: 亞系券商 | F20: 亞系券商考量電視需求疲弱與價格停滯，預期明年缺乏明顯成長催化劑。且認為股息吸引力下降，故降評至中性。 | G20: #IC設計 #電視
A21: 020 | C21: SK海力士 三星電子 | E21: 瑞銀 | F21: • 外電引述瑞銀最新報告顯示，存儲晶片產業已步入「嚴重短缺」期，2025年第四季DDR合約價談判明顯轉強，單季環比漲幅預估達21%或更高，供應商重新掌握定價權，價格上行週期有望延續至2026年底、甚至推進至2027年第一季。 • 瑞銀據此上調兩大韓系龍頭評等與預期：將SK海力士12個月目標價自64萬韓元調升至71萬韓元，維持「買進」並稱其為內存領域「首選」；三星電子目標價自11. • 8萬韓元上調至12.8萬韓元，同步上調2026-2027年營收與獲利假設。 • 報告寫到，價格驅動的核心在於結構性供需失衡：AI帶動的高帶寬記憶體(HBM)需求爆發、傳統伺服器更新週期持續、企業級SSD受AI與HDD短缺帶動額外需求，再加上前段晶圓產能優先傾斜至高毛利HBM，擠壓傳統DDR供給，使DRAM議價權明顯回到供應端。 | G21: #DRAM #DDR #HBM #記憶體
A22: 021 | B22: 2025/10/28 | C22: 貿聯 | D22: 3665 | E22: 美系大行 | F22: • 美系大行上修25-27年EPS至$43.8/$57.8/$69. • 8，給予明年30xPE評價，同步升目標。 • 券商指出AEC 過去只有一家ASIC在使用，從今年下半年開始已陸續導入多家CSP的GPU伺服器，主要用在scale-out 架構上，未來scale-up 上也有龐大潛力市場。 • 再來，另個產品領域：電源互連（Power Interconnect），近月也得到許多關注，應用在GB200/300 與 VR 機櫃等，預估今明年貢獻營收比達5%/10%。 | G22: #AEC #電源互連 #GPU
A23: 022 | B23: 2025/10/28 | C23: 奇鋐 | D23: 3017 | E23: 亞系券商 | F23: • 亞系券商調升25-27年EPS至$46.7/$63.4/$77. • 2，以29xPE評價，同步升目標。 • 券商指出3Q毛利率有望達到歷史高的26.7%，短期（4Q25-1Q26)仍舊受益於強勁的ASIC & GPU訂單能見度。 • 中長期：觀察明下半年水冷案更多，持續保持領先地位，預期明年越南產能至少還要擴充出5成。 • 綜上，調升25-27年財務模型預估。 | G23: #水冷 #ASIC #GPU
A24: 023 | B24: 2025/10/28 | C24: 景碩 | D24: 3189 | E24: 美系券商 | F24: • 3Q result 不如美系券商預期，券商認為來自成本上升，而BT/ABF漲價效應要在1-2個月後才會顯現，因此，認為4Q毛利率能上升6 個百分點至 25%，帶動獲利季增100%。 • 至於現增案，券商認為主要因應擴廠需求，若全數執行恐稀釋15%，不過券商表示這只是預先公告，實際籌資金額與投資規模仍在討論中。 | G24: #BT #ABF #現增
A25: 024 | B25: 2025/10/29 | C25: 國巨 | D25: 2327 | E25: 美系大行 | F25: • 美系大行將國巨的評等調升為正向，同時調高25-27年EPS至$11. • 3/$14.1/$16.4，給予明年20.5xPE評價，同步升目標。 • 券商早在2022年就指出國巨轉型為全球電子零件整合供應商。 • 展望4Q，預期優於季節性表現；受惠於電子產業需求增強、鉭電容價格上漲，以及芝浦電子（Shibaura）併購整合。 • 預估4Q營收季增4%，毛利率預期季增 0.5 個百分點至 36. • 3%，主因鉭電容售價上升及併購芝浦電子效益。 • 預估4Q EPS $3.21。 • 總體產能利用率預期與3Q持平，明年進一步上升。 | G25: #被動元件 #鉭電容
A26: 025 | B26: 2025/10/29 | C26: 京元電 日月光 | D26: 2449 3711 | E26: 美系大行 | F26: • 美系大行指出半導體通膨（價格上漲）已經開始了；台積電漲價、記憶體供應商的報價能力提升、預期矽晶圓片也會上漲，認為漲勢也會延續到封測。 • 預估先進封裝價格將上漲 5–10%，這是自 COVID-19 晶片短缺以來首次漲價潮。 • 在眾廠之中，券商偏好京元電，因其獲利能力如EBITDA 利潤率顯著優於同業，且在探針與 ASIC 測試市場持續擴大市佔。 • *上修京元電25-27年EPS至$8.8/$9.5/$13. • 6，給予明年14xPE評價，公布升目標。 • 反映AI GPU 測試需求強勁、ASIC 測試滲透率上升、及 AI 收入佔比提升，目前產能吃緊。 • *上修日月光25-27年至$8.6/$14/$20.1，給予明年16xPE評價。 • 同樣面臨產能吃緊，預期逐步將部分傳統打線封裝產線轉為flip-chip封裝以支援更多 AI 相關需求。 • 產品組合優化且ASP提升，因此上修獲利預估。 | G26: #封測 #漲價 #AI
A27: 026 | B27: 2025/10/29 | C27: 聯發科 | D27: 2454 | E27: 美系大行 | F27: • 美系大行承上觀察：因成本都在上升，但認為難以轉嫁成本。 • 且DRAM+NAND 成本約為 110 美元，與高階天璣 9400 晶片售價（110–120 美元）相近。 • 券商預估4Q營收季增0-5%，但毛利率降至47%，反映中低階 5G SoC 競爭激烈。 • 下修明後年EPS至$69.3/$93.8，同步降目標。 | G27: #天璣 #成本上升
A28: 027 | B28: 2025/10/29 | C28: 致茂 | D28: 2360 | E28: 美系大行 | F28: • 美系大行上修25-27年EPS至$18.4/$23.4/$27. • 4，以明年35xPE評價，同步升目標。 • 券商預期電源與半導體測試推動成長。 • 由於每機櫃功率上升，需使用更高密度電源供應器（PSU）及備援電池（BBU），為測試業務帶來額外成長機會。 • 預估預估電源測試營收今明年年增幅 49% /38%。 • 半導體類，下一輪 AI GPU CoWoS 封裝週期將於 2025 年底至 2026 年初啟動，更高密度量測應用（如晶圓級多晶片模組 WLCM）將帶來新需求。 • 預估半導體與光電相關業務今明年營收增幅43% /41%。 | G28: #測試設備 #PSU #BBU
A29: 028 | B29: 2025/10/29 | C29: 欣興 | D29: 3037 | E29: 美系券商 | F29: • 3Q result不如美系預期，因成本上升，但漲價效應要到4Q才會展現。 • 預期4Q營收季增3%，ABF/BT 售價提升及 ABF 訂單動能改善，不過HDI 與 PCB 因消費性電子產業進入淡季。 • 預期明年年中動能來自新一代 CPO 基板，規格可能達 150mm × 150mm × 28 層，單價約 300–400 美元。 | G29: #ABF #BT #CPO
A30: 029 | B30: 2025/11/06 | C30: 華邦電 | D30: 2344 | E30: 美系大行 | F30: • 法說會後，美系大行再升目標，重申「首選」。 • 評價：上修至2026年的2.6倍P/B。 • 上修25-27年EPS至$1.14/$4.3/$7.2。 • 券商持續看好華邦電在DDR、NOR與SLC NAND的報價上升，以及未來CUBE擴產。 • 展望4Q，券商強調結構性的供應吃緊支撐營運表現，且4Q就算沒有庫存評價回沖，預期毛利率表現也能維持跟3Q相當。 • 上月宣布的355億元將用於高雄記憶體擴廠，計畫將晶圓產能由每月1. • 5萬片提升至2.4～2.5萬片，並隨16奈米產能擴充而使bit出貨量翻倍。 | G30: #DDR #NOR #CUBE
A31: 030 | B31: 2025/11/06 | C31: 金像電 | D31: 2368 | E31: 亞系券商 | F31: • 恭喜入MSCI 台灣指數！ • 亞系券商調升25-27年EPS至$17.7/$26.3/$30. • 8，給予明年25xPE評價，同步升目標。 • 券商認為4Q將有優於市場之前悲觀預期的表現，預估營收季持平，延續3Q 高層數（64–80 層）800G switch PCB強勁需求。 • 明上半年隨AI PCB需求能見度提升而迎來復甦。 • 另外也上修3Q毛利率至34%（～前預估為31.9%），因因AWS ASIC需求及泰國廠順利擴產。 | G31: #AI PCB #800G #MSCI
A32: 031 | B32: 2025/11/06 | C32: 東元 | D32: 1504 | E32: 美系券商 | F32: • 恭喜入MSCI 台灣指數！ • 美系券商預估3Q毛利率將提升至24.6%（上半年為23.8%），主要受智慧工程（IE）業務（資料中心與離岸風電專案）的毛利改善帶動。 • 預估4Q營收季增12%、年增22%，馬達業務復甦、智慧工程加速成長，另外變壓器組裝產能明後年也先後在中壢、桃園擴產。 • 券商上修今明年EPS至$2.43/$4.6，同步升目標。 | G32: #馬達 #資料中心 #MSCI
A33: 032 | B33: 2025/11/06 | C33: 貿聯 | D33: 3665 | E33: 美系大行 | F33: • 恭喜入MSCI 台灣指數！ • 營收QTD達成券商預估數的33%，符合美系大行預估、優於市場預估。 • HPC事業成長強勁，由AEC及電源需求持續帶動。 • 維持正向評等不變。 | G33: #AEC #HPC #MSCI
A34: 033 | B34: 2025/11/06 | C34: 鴻海 | D34: 2317 | E34: 美系大行 | F34: • 10月營收新高！ • 美系大行先暫維持4Q營收季增19%的預估，待11/12法說會指引。 • 同時券商預估3Q毛利率上升至6.2%，OPM 3.3%。 • 各產品線如伺服器及消費性都同步成長。 • 維持正向評等不變。 | G34: #10月營收新高 #伺服器
A35: 034 | B35: 2025/11/06 | C35: 南電 | D35: 8046 | E35: 美系券商 | F35: • 美系券商認為3Q毛利率與營益率如預期改善，展望4Q, 預期營收季增4%，主要受惠於ABF與BT載板價格提升（預估ABF/BT單季價格分別上漲3–5%與10–15%）。 • 預期4Q毛利率將再上升2.6個百分點至12.9%（第3季為9. • 6%）。 | G35: #ABF #BT #漲價
A36: 035 | B36: 2025/11/03 | C36: 聯發科 | D36: 2454 | E36: 美系券商 | F36: • 法說會後，一家美系降評，下修25-27年EPS為$67.1/$70/$89. • 9，同步降目標。 • 券商調降明後年毛利率至45.9%/45.3%，OPM降至17. • 0%/18.6%，反映成本上揚、研發支出增、主要產品毛利率被稀釋及ASIC業務對當前營運槓桿有限。 | G36: #毛利率下降 #ASIC
A37: 036 | B37: 2025/11/03 | C37: 散熱產業 奇鋐 富世達 雙鴻 建準 | D37: 3017 6805 3324 2421 | E37: 美系大行 | F37: • 美系大行表示GB300 伺服器機櫃的散熱元件價值將較 GB200 提升 200%，VR 對GB300伺的散熱元件價值再提升 17%。 • 且Vera Rubin computing trays 可能採標準化設計，對奇鋐、富世達正面解讀，尤其還是採用cold plate，Rubin Ultra 可能採用的MCCP/MCL等進階要到明年下半年才定案。 • ASIC方面：AWS Trainium 3 與 Meta 的 MTIA 專案都將採用水冷設計，Google TPU 明年轉向亞洲供應鏈。 • 綜上，鑑於水冷滲透率明年大幅提高，券商上修覆蓋裡的獲利預估，同步升目標。 • *升目標：3017奇鋐、6805富世達、3324雙鴻、2421建準 | G37: #GB300 #水冷 #散熱
A38: 037 | B38: 2025/11/03 | C38: 國巨 | D38: 2327 | E38: 美系券商 | F38: • 美系券商上修25-27年EPS至$11.3/$17.6/$22. • 3，給予15x明年PB/ROE評價，同步升目標。 • 券商對上週法說會內容正向解讀，鉭質電容需求持續強勁，供需吃緊，將擴增墨西哥廠10-15%產能。 • 除了鉭質電容外，券商認為其他被動元件雖暫無漲價空間，但需求復甦正在各產品線發生，中期可望帶動營收展望改善。 • 中國/亞洲經銷商的庫存水位僅約3個月。 | G38: #被動元件 #鉭電容
A39: 038 | B39: 2025/11/03 | C39: 嘉澤 | D39: 3533 | E39: 美系大行 | F39: • 美系大行下修25-27年EPS至$67.8/$89.1/$101. • 2，以明年17xPE評價，同步降目標。 • 券商主要認為SOC/AMD與QD插槽需求將於2026年下半年末起放量，主要貢獻落在2027年。 • 另以 QD 而言，GB300 compute tray採混合液冷設計（hybrid-cooled）僅搭載6組QD模組。 • 券商認為嘉澤的QD 營收貢獻需待 Nvidia 下一代 VR200 平台於下半年放量後才會顯著。 | G39: #QD #VR200
A40: 039 | B40: 2025/10/31 | C40: AI供應鏈 | D40: - | E40: 美系大行 | F40: • 美系大行針對CoWoS產能更新如下： **台積電陣營： *AMD上修：從 8 萬片增加至 9 萬片，反映即將推出的 MI400 系列需求。 • *Broadcom：無變化。 • 即便 Anthropic 宣布採用 TPU但券商認為 Broadcom 在向台積電下單時已將這「第四家客戶」納入。 • 維持明年2.8mn。 • *聯發科：無變化。 • 維持TPU 約 0.2m 顆。 • *AWS Trainium3 ：無變化。 • 2026 年出貨量預估維持1.2m。 • Anthropic仍以 AWS 為主要雲端服務夥伴與訓練平台，因此不構成衝擊。 • **非台積電陣營：上修 券商認為受惠台積電 CoWoS 產能吃緊外溢的需求，上修預估如下： *日月光與矽品的 FoCoS／CoWoS 產能至今年底達 8,000 片/月，明年進一步擴充至 2 萬片/月。 • 有包括Broadcom TPU, Tomahawk switch、CEVP 及 AWS Trainium 3/2。 • *Amkor亦預期於年底達 1.5 萬片/月，明年擴增至 2 萬片/月。 • 支援 NVIDIA 的 Vera CPU 及非 GPU 產品，例如 N1X、車用晶片與 GB10。 | G40: #CoWoS #AMD #Broadcom
A41: 040 | B41: 2025/10/31 | C41: 京元電 | D41: 2449 | E41: 亞系券商 | F41: • 亞系上修25-27年EPS至8.3/$8.3/$10。 • 券商認為除了Nviida還受惠於其他Broadcom、聯發科、Google TPU 等AI ASIC 客戶。 • 預期ASIC 收入佔比可達 25–28%，同步推升毛利率表現。 | G41: #ASIC #TPU
A42: 041 | B42: 2025/10/31 | C42: 日月光 | D42: 3711 | E42: 美系大行 | F42: • 美系大行表示毛利率向上擴張穩在軌道上。 • 3Q毛利率為 17.1%，高於美系大行與市場共識的預估，預期4Q毛利率季增70-100bps。 • 封裝與測試利用率 維持在高水位，LEAP 與傳統進階封裝線幾乎滿載，明年持續擴大資本支出。 | G42: #封裝 #LEAP
A43: 042 | B43: 2025/10/31 | C43: 川湖 | D43: 2059 | E43: 美系大行 | F43: • 美系大行再度上修25-27年EPS至$87.8/$130.8/$147. • 8。 • 券商認為3Q毛利率雖受匯率影響，但預期領導地位仍在。 • 展望4Q, 預期營收季增5%，毛利率74.9%。 • 預期明年營收成長近3成，預期是AMD Helios 機櫃的潛在合作夥伴。 | G43: #機櫃 #AMD Helios
A44: 043 | B44: 2025/10/31 | C44: 台達電 | D44: 2308 | E44: 美系大行 | F44: • 美系大行上修25-27年至$23.7/$35/$42。 • 券商點出OPM是關鍵，雖研發與行銷費用仍占營收 15–20%，但預期 2024–2027 年營收年複合成長率達 27%，足以推動長期毛利率持續上升。 • Infra的OPM 上升至16.5%，顯示規模經濟效應逐步顯現。 • 維持「首選」。 | G44: #Infra #OPM #首選
...

Sheet 產業趨勢專區
A1: 編號 | B1: 日期 | C1: 產業主題 | D1: 券商來源 | E1: 完整內容 | F1: 相關公司群 | G1: 標籤
A2: T001 | B2: 2025/11/10 | C2: GB200/GB300機櫃出貨 | D2: 美系大行 | E2: • 美系大行預估4Q總機櫃出貨量可望顯著成長至14,000–15,000台，高於第3季的8,000–8,500台。 • GB300生產已啟動，將順利放量，未聞任何良率問題。 | F2: 緯穎(6669)、廣達(2382)、英業達(2356)、鴻海(2317) | G2: #GB200 #GB300 #NVL72 #AI伺服器
A3: T002 | B3: 2025/10/31 | C3: AI供應鏈CoWoS產能追蹤 | D3: 美系大行 | E3: • 美系大行針對CoWoS產能更新：台積電陣營AMD上修至9萬片（MI400需求）、Broadcom維持2. • 8mn、聯發科維持0.2m、AWS Trainium3維持1. • 2m。 • 非台積電陣營：日月光與矽品FoCoS/CoWoS產能年底達8K片/月、明年擴至2萬片/月；Amkor年底達1. • 5萬片/月、明年擴至2萬片/月。 | F3: AMD、Broadcom、聯發科、AWS、日月光(3711)、矽品、Amkor | G3: #CoWoS #AMD #Broadcom #日月光
A4: T003 | B4: 2025/11/03 | C4: 散熱產業趨勢 | D4: 美系大行 | E4: • GB300伺服器機櫃的散熱元件價值較GB200提升200%，VR對GB300再提升17%。 • Vera Rubin computing trays可能採標準化設計（cold plate）。 • ASIC方面AWS Trainium 3與Meta MTIA都採水冷設計，Google TPU明年轉向亞洲供應鏈。 • 水冷滲透率明年大幅提高。 | F4: 奇鋐(3017)、富世達(6805)、雙鴻(3324)、建準(2421) | G4: #GB300 #水冷 #散熱 #ASIC
A5: T004 | B5: 2025/10/29 | C5: 封測產業漲價潮 | D5: 美系大行 | E5: • 半導體通膨已經開始：台積電漲價、記憶體報價能力提升、矽晶圓片預期上漲，漲勢延續到封測。 • 預估先進封裝價格將上漲5-10%，這是自COVID-19晶片短缺以來首次漲價潮。 | F5: 京元電(2449)、日月光(3711)、其他封測廠 | G5: #封測 #漲價 #先進封裝
A6: T005 | B6: 2025/10/27 | C6: Vertiv財報解讀 | D6: 美系大行 | E6: • 3Q營收季增2成、年增6成，BB ratio上升至1.4x。 • 公司guide 4Q營收續增，還要擴充產能。 | F6: 台達電(2308)、奇鋐(3017)、富世達(6805) | G6: #Vertiv #AI伺服器
A7: T006 | B7: 2025/10/21 | C7: OCP大會四大重點 | D7: 美系大行 | E7: • AMD的Helios機櫃、800V直流電架構、Google Deschutes 2MW CDU以及ESUN網路。 • GB300運算模組已進入量產階段，採用85%液冷+15%氣冷混合設計。 • 次世代VR200正在測試，預計2026年3Q投入生產。 | F7: AMD、Meta、Google、Nvidia | G7: #OCP #Helios #800VDC #GB300 #VR200
A8: T007 | B8: 2025/10/07 | C8: PCB產業觀察-BT雙位數缺口 | D8: 美系券商 | E8: • T-glass短缺對BT影響比預期嚴重。 • 預期未來會有雙位數供給缺口，且預期會有5-10%實質漲價。 • PCB/CCL有供給缺口，狀況會延續到明年2-3季。 | F8: PCB產業、CCL產業 | G8: #BT #T-glass #供給缺口
A9: T008 | B9: 2025/10/03 | C9: OpenAI供應鏈 | D9: 美系券商 | E9: OpenAI新宣布10GW專案相當於8萬台以上GB200 NVL72機櫃，或2,500億美元機櫃層級資本支出。 | F9: 台積電(2330)、日月光(3711)、欣興(3037)、南亞科(2408)、台達電(2308) | G9: #OpenAI #10GW #GB200
A10: T009 | B10: 2025/08/28 | C10: AI股票策略 | D10: 日系券商 | E10: • 亞太地區和新興市場AI採用者比例從30%升至34%。 • AI重要性為中等或更高的公司從24%升至31%。 • 看到從半導體產業向基礎設施和應用型企業輪動跡象。 • 採用AI且具高定價能力的公司表現優於其他公司。 | F10: 迅銷(9983)、Recruit holdings(6098)、Secom(9753) | G10: #AI應用 #產業輪動 #日股
A11: T010 | B11: 2025/08/28 | C11: 日本半導體設備產業 | D11: 日系券商 | E11: • 台積電N2製程不再使用中國產SPE，可能回應美國中國EQUIP法案。 • 東京威力科創(8035)在蝕刻系統領域競爭。 • SCREEN(7735)和國際電氣(6525)將受益。 • 中國製造商在清洗系統和垂直熱處理爐技術進步構成威脅。 | F11: 東京威力科創(8035)、SCREEN(7735)、國際電氣(6525) | G11: #半導體設備 #台積電 #日股
A12: T011 | B12: 2025/08/26 | C12: ABF產業漲價潮 | D12: 美系券商 | E12: • non-NVDA ABF報價2025Q4起每季上漲5-10%，延續到2026Q4。 • T-glass短缺將更嚴重，BT/高階ABF年底供給短缺。 • 主要受惠者：南電（50-55%曝險）。 • 次要受惠者：臻鼎（BT與ABF曝險約20%）。 | F12: 南電(8046)、景碩(3189)、臻鼎(4958)、欣興(3037) | G12: #ABF #BT #T-glass #漲價
... A60: T059 | B60: 2025/05/09 | C60: GB200 NVL72出貨追蹤 | D60: 美系大行 | E60: • 觀察GB200 NVL72 4月份開始出貨增加。 • 全月出了1.5k vs 第一季整季的1k。 • 其中廣達300-400，緯創100-150，鴻海1k。 | F60: 廣達(2382)、緯創(3231)、鴻海(2317) | G60: #4月1.5k #1Q僅1k #鴻海1k

Sheet 公司代碼對照
A1: 公司名稱 | B1: 股號
A2: AI供應鏈 | B2: -
A3: Celestica/智邦 | B3: 2345
A4: SK海力士
A5: 三星電子
A6: 世界 | B6: 5347
A7: 京元電 | B7: 2449
A8: 光寶科 | B8: 2301
A9: 創意 | B9: 3443
A10: 勤誠 | B10: 8210
A11: 南電 | B11: 8046
A12: 台光電 | B12: 2383
A13: 台達電 | B13: 2308
A14: 嘉澤 | B14: 3533
A15: 國巨 | B15: 2327
A16: 奇鋐 | B16: 3017
A17: 富世達 | B17: 6805
... A38: 鴻海 | B38: 2317

Sheet 使用說明
A1: 📖 外電綜合報導資料庫 - 使用說明
A3: 📊 工作表說明
A5: 1. 公司查詢 | B5: → | C5: 快速查詢特定公司的所有報導
A6: 2. 報導總表 | B6: → | C6: 所有報導的摘要列表，可篩選排序
A7: 3. 完整內容收錄 | B7: → | C7: 保存完整原始報導內容
A8: 4. 產業趨勢專區 | B8: → | C8: 產業面的重要趨勢報導
A9: 5. 公司代碼對照 | B9: → | C9: 查詢公司名稱與股號對照
A12: 🔍 如何使用「公司查詢」
A14: 步驟1： | B14: 前往「公司查詢」工作表
A15: 步驟2： | B15: 在輸入框中輸入股號（如：3017）或公司名稱（如：奇鋐）
A16: 步驟3： | B16: 按Enter，手動篩選結果
A18: 💡 提示： | B18: 可使用「報導總表」的篩選功能查看特定日期或券商的報導
A21: ⭐ 重要性等級說明
A23: ⭐⭐⭐⭐⭐ | B23: → | C23: 極重要（重大財務調整、關鍵產業趨勢）
A24: ⭐⭐⭐⭐ | B24: → | C24: 重要（重要營運展望、市佔變化）
A25: ⭐⭐⭐ | B25: → | C25: 一般（追蹤報導、法說會前瞻）
A26: ⭐⭐ | B26: → | C26: 參考（降評、次要資訊）

Sheet 查詢輔助
A1: 原始列號 | B1: 符合條件 | C1: 累計筆數
A2: 1 | B2: =IF(公司查詢!$A$4="",0,IF(OR(完整內容收錄!D2=公司查詢!$A$4,ISNUMBER(SEARCH(公司查詢!$A$4,完整內容收錄!C2))),1,0)) | C2: =B2
A3: 2 | B3: =IF(公司查詢!$A$4="",0,IF(OR(完整內容收錄!D3=公司查詢!$A$4,ISNUMBER(SEARCH(公司查詢!$A$4,完整內容收錄!C3))),1,0)) | C3: =B3+C2
A4: 3 | B4: =IF(公司查詢!$A$4="",0,IF(OR(完整內容收錄!D4=公司查詢!$A$4,ISNUMBER(SEARCH(公司查詢!$A$4,完整內容收錄!C4))),1,0)) | C4: =B4+C3
A5: 4 | B5: =IF(公司查詢!$A$4="",0,IF(OR(完整內容收錄!D5=公司查詢!$A$4,ISNUMBER(SEARCH(公司查詢!$A$4,完整內容收錄!C5))),1,0)) | C5: =B5+C4
A6: 5 | B6: =IF(公司查詢!$A$4="",0,IF(OR(完整內容收錄!D6=公司查詢!$A$4,ISNUMBER(SEARCH(公司查詢!$A$4,完整內容收錄!C6))),1,0)) | C6: =B6+C5
A7: 6 | B7: =IF(公司查詢!$A$4="",0,IF(OR(完整內容收錄!D7=公司查詢!$A$4,ISNUMBER(SEARCH(公司查詢!$A$4,完整內容收錄!C7))),1,0)) | C7: =B7+C6
A8: 7 | B8: =IF(公司查詢!$A$4="",0,IF(OR(完整內容收錄!D8=公司查詢!$A$4,ISNUMBER(SEARCH(公司查詢!$A$4,完整內容收錄!C8))),1,0)) | C8: =B8+C7
A9: 8 | B9: =IF(公司查詢!$A$4="",0,IF(OR(完整內容收錄!D9=公司查詢!$A$4,ISNUMBER(SEARCH(公司查詢!$A$4,完整內容收錄!C9))),1,0)) | C9: =B9+C8
A10: 9 | B10: =IF(公司查詢!$A$4="",0,IF(OR(完整內容收錄!D10=公司查詢!$A$4,ISNUMBER(SEARCH(公司查詢!$A$4,完整內容收錄!C10))),1,0)) | C10: =B10+C9
A11: 10 | B11: =IF(公司查詢!$A$4="",0,IF(OR(完整內容收錄!D11=公司查詢!$A$4,ISNUMBER(SEARCH(公司查詢!$A$4,完整內容收錄!C11))),1,0)) | C11: =B11+C10
A12: 11 | B12: =IF(公司查詢!$A$4="",0,IF(OR(完整內容收錄!D12=公司查詢!$A$4,ISNUMBER(SEARCH(公司查詢!$A$4,完整內容收錄!C12))),1,0)) | C12: =B12+C11
A13: 12 | B13: =IF(公司查詢!$A$4="",0,IF(OR(完整內容收錄!D13=公司查詢!$A$4,ISNUMBER(SEARCH(公司查詢!$A$4,完整內容收錄!C13))),1,0)) | C13: =B13+C12
A14: 13 | B14: =IF(公司查詢!$A$4="",0,IF(OR(完整內容收錄!D14=公司查詢!$A$4,ISNUMBER(SEARCH(公司查詢!$A$4,完整內容收錄!C14))),1,0)) | C14: =B14+C13
... A51: 50 | B51: =IF(公司查詢!$A$4="",0,IF(OR(完整內容收錄!D51=公司查詢!$A$4,ISNUMBER(SEARCH(公司查詢!$A$4,完整內容收錄!C51))),1,0)) | C51: =B51+C50
B52: =IF(公司查詢!$A$4="",0,IF(OR(完整內容收錄!D52=公司查詢!$A$4,ISNUMBER(SEARCH(公司查詢!$A$4,完整內容收錄!C52))),1,0)) | C52: =B52+C51
B53: =IF(公司查詢!$A$4="",0,IF(OR(完整內容收錄!D53=公司查詢!$A$4,ISNUMBER(SEARCH(公司查詢!$A$4,完整內容收錄!C53))),1,0)) | C53: =B53+C52
B54: =IF(公司查詢!$A$4="",0,IF(OR(完整內容收錄!D54=公司查詢!$A$4,ISNUMBER(SEARCH(公司查詢!$A$4,完整內容收錄!C54))),1,0)) | C54: =B54+C53
B55: =IF(公司查詢!$A$4="",0,IF(OR(完整內容收錄!D55=公司查詢!$A$4,ISNUMBER(SEARCH(公司查詢!$A$4,完整內容收錄!C55))),1,0)) | C55: =B55+C54
B56: =IF(公司查詢!$A$4="",0,IF(OR(完整內容收錄!D56=公司查詢!$A$4,ISNUMBER(SEARCH(公司查詢!$A$4,完整內容收錄!C56))),1,0)) | C56: =B56+C55
B57: =IF(公司查詢!$A$4="",0,IF(OR(完整內容收錄!D57=公司查詢!$A$4,ISNUMBER(SEARCH(公司查詢!$A$4,完整內容收錄!C57))),1,0)) | C57: =B57+C56
B58: =IF(公司查詢!$A$4="",0,IF(OR(完整內容收錄!D58=公司查詢!$A$4,ISNUMBER(SEARCH(公司查詢!$A$4,完整內容收錄!C58))),1,0)) | C58: =B58+C57
B59: =IF(公司查詢!$A$4="",0,IF(OR(完整內容收錄!D59=公司查詢!$A$4,ISNUMBER(SEARCH(公司查詢!$A$4,完整內容收錄!C59))),1,0)) | C59: =B59+C58
B60: =IF(公司查詢!$A$4="",0,IF(OR(完整內容收錄!D60=公司查詢!$A$4,ISNUMBER(SEARCH(公司查詢!$A$4,完整內容收錄!C60))),1,0)) | C60: =B60+C59
B61: =IF(公司查詢!$A$4="",0,IF(OR(完整內容收錄!D61=公司查詢!$A$4,ISNUMBER(SEARCH(公司查詢!$A$4,完整內容收錄!C61))),1,0)) | C61: =B61+C60
B62: =IF(公司查詢!$A$4="",0,IF(OR(完整內容收錄!D62=公司查詢!$A$4,ISNUMBER(SEARCH(公司查詢!$A$4,完整內容收錄!C62))),1,0)) | C62: =B62+C61
B63: =IF(公司查詢!$A$4="",0,IF(OR(完整內容收錄!D63=公司查詢!$A$4,ISNUMBER(SEARCH(公司查詢!$A$4,完整內容收錄!C63))),1,0)) | C63: =B63+C62
... B250: =IF(公司查詢!$A$4="",0,IF(OR(完整內容收錄!D250=公司查詢!$A$4,ISNUMBER(SEARCH(公司查詢!$A$4,完整內容收錄!C250))),1,0)) | C250: =B250+C249
